2024-10-23 11:03:23,319 INFO    Thread-15 (_run_job):15244 [wandb_setup.py:_flush():79] Current SDK version is 0.18.3
2024-10-23 11:03:23,319 INFO    Thread-15 (_run_job):15244 [wandb_setup.py:_flush():79] Configure stats pid to 15244
2024-10-23 11:03:23,319 INFO    Thread-15 (_run_job):15244 [wandb_setup.py:_flush():79] Loading settings from C:\Users\31614\.config\wandb\settings
2024-10-23 11:03:23,319 INFO    Thread-15 (_run_job):15244 [wandb_setup.py:_flush():79] Loading settings from C:\Users\31614\Documents\AI_course_stuff\RLForaging Thesis\RLForagingAgents\RL-models\TD3\wandb\settings
2024-10-23 11:03:23,319 INFO    Thread-15 (_run_job):15244 [wandb_setup.py:_flush():79] Loading settings from environment variables: {'project': 'Pendulum-TD3', 'entity': 'senna-renting-radboud-university', 'root_dir': 'C:\\Users\\31614\\Documents\\AI_course_stuff\\RLForaging Thesis\\RLForagingAgents\\RL-models\\TD3', 'run_id': '683jggrk', 'sweep_param_path': 'C:\\Users\\31614\\Documents\\AI_course_stuff\\RLForaging Thesis\\RLForagingAgents\\RL-models\\TD3\\wandb\\sweep-st6aw9n2\\config-683jggrk.yaml', 'sweep_id': 'st6aw9n2'}
2024-10-23 11:03:23,324 INFO    Thread-15 (_run_job):15244 [wandb_setup.py:_flush():79] Applying setup settings: {'mode': None, '_disable_service': None}
2024-10-23 11:03:23,324 INFO    Thread-15 (_run_job):15244 [wandb_setup.py:_flush():79] Inferring run settings from compute environment: {'program': '<python with no main file>'}
2024-10-23 11:03:23,324 INFO    Thread-15 (_run_job):15244 [wandb_setup.py:_flush():79] Applying login settings: {}
2024-10-23 11:03:23,324 INFO    Thread-15 (_run_job):15244 [wandb_init.py:_log_setup():532] Logging user logs to C:\Users\31614\Documents\AI_course_stuff\RLForaging Thesis\RLForagingAgents\RL-models\TD3\wandb\run-20241023_110323-683jggrk\logs\debug.log
2024-10-23 11:03:23,324 INFO    Thread-15 (_run_job):15244 [wandb_init.py:_log_setup():533] Logging internal logs to C:\Users\31614\Documents\AI_course_stuff\RLForaging Thesis\RLForagingAgents\RL-models\TD3\wandb\run-20241023_110323-683jggrk\logs\debug-internal.log
2024-10-23 11:03:23,324 INFO    Thread-15 (_run_job):15244 [wandb_init.py:_jupyter_setup():478] configuring jupyter hooks <wandb.sdk.wandb_init._WandbInit object at 0x000001E3A68285F0>
2024-10-23 11:03:23,324 INFO    Thread-15 (_run_job):15244 [wandb_init.py:init():617] calling init triggers
2024-10-23 11:03:23,324 INFO    Thread-15 (_run_job):15244 [wandb_init.py:init():624] wandb.init called with sweep_config: {'batch_size': 64, 'buffer_size': 50000, 'gamma': 0.99, 'lr_actor': 0.0004923515374974485, 'lr_critic': 0.0015628199667046968, 'max_length_episode': 200, 'noise_clip': 0.5050267382189233, 'num_episodes': 100, 'policy_interval': 2, 'sigma': 0.5351239357469288, 'sigma_explore': 0.93945673848919, 'tau': 0.22630848856663255, 'warmup_amount': 500}
config: {}
2024-10-23 11:03:23,324 INFO    Thread-15 (_run_job):15244 [wandb_init.py:init():667] starting backend
2024-10-23 11:03:23,324 INFO    Thread-15 (_run_job):15244 [wandb_init.py:init():671] sending inform_init request
2024-10-23 11:03:23,335 INFO    Thread-15 (_run_job):15244 [backend.py:_multiprocessing_setup():104] multiprocessing start_methods=spawn, using: spawn
2024-10-23 11:03:23,335 INFO    Thread-15 (_run_job):15244 [wandb_init.py:init():684] backend started and connected
2024-10-23 11:03:23,352 INFO    Thread-15 (_run_job):15244 [wandb_run.py:_config_callback():1394] config_cb None None {'batch_size': 64, 'buffer_size': 50000, 'gamma': 0.99, 'lr_actor': 0.0004923515374974485, 'lr_critic': 0.0015628199667046968, 'max_length_episode': 200, 'noise_clip': 0.5050267382189233, 'num_episodes': 100, 'policy_interval': 2, 'sigma': 0.5351239357469288, 'sigma_explore': 0.93945673848919, 'tau': 0.22630848856663255, 'warmup_amount': 500}
2024-10-23 11:03:23,352 INFO    Thread-15 (_run_job):15244 [wandb_run.py:_label_probe_notebook():1346] probe notebook
2024-10-23 11:03:23,353 INFO    Thread-15 (_run_job):15244 [wandb_run.py:_label_probe_notebook():1356] Unable to probe notebook: 'NoneType' object has no attribute 'get'
2024-10-23 11:03:23,353 INFO    Thread-15 (_run_job):15244 [wandb_init.py:init():779] updated telemetry
2024-10-23 11:03:23,389 INFO    Thread-15 (_run_job):15244 [wandb_init.py:init():812] communicating run to backend with 90.0 second timeout
2024-10-23 11:03:23,599 INFO    Thread-15 (_run_job):15244 [wandb_init.py:init():863] starting run threads in backend
2024-10-23 11:03:23,790 WARNING MsgRouterThr:15244 [router.py:message_loop():77] message_loop has been closed
2024-10-23 11:03:24,175 ERROR   Thread-15 (_run_job):15244 [wandb_init.py:init():1262] error in wandb.init()
Traceback (most recent call last):
  File "C:\Users\31614\anaconda3\Lib\site-packages\wandb\sdk\wandb_init.py", line 1252, in init
    return wi.init()
           ^^^^^^^^^
  File "C:\Users\31614\anaconda3\Lib\site-packages\wandb\sdk\wandb_init.py", line 906, in init
    run._on_start()
  File "C:\Users\31614\anaconda3\Lib\site-packages\wandb\sdk\wandb_run.py", line 2505, in _on_start
    self._backend.interface.publish_python_packages(working_set())
  File "C:\Users\31614\anaconda3\Lib\site-packages\wandb\sdk\interface\interface.py", line 303, in publish_python_packages
    self._publish_python_packages(python_packages)
  File "C:\Users\31614\anaconda3\Lib\site-packages\wandb\sdk\interface\interface_shared.py", line 390, in _publish_python_packages
    self._publish(rec)
  File "C:\Users\31614\anaconda3\Lib\site-packages\wandb\sdk\interface\interface_sock.py", line 51, in _publish
    self._sock_client.send_record_publish(record)
  File "C:\Users\31614\anaconda3\Lib\site-packages\wandb\sdk\lib\sock_client.py", line 225, in send_record_publish
    self.send_server_request(server_req)
  File "C:\Users\31614\anaconda3\Lib\site-packages\wandb\sdk\lib\sock_client.py", line 157, in send_server_request
    self._send_message(msg)
  File "C:\Users\31614\anaconda3\Lib\site-packages\wandb\sdk\lib\sock_client.py", line 154, in _send_message
    self._sendall_with_error_handle(header + data)
  File "C:\Users\31614\anaconda3\Lib\site-packages\wandb\sdk\lib\sock_client.py", line 132, in _sendall_with_error_handle
    sent = self._sock.send(data)
           ^^^^^^^^^^^^^^^^^^^^^
ConnectionResetError: [WinError 10054] An existing connection was forcibly closed by the remote host
2024-10-23 11:03:24,475 INFO    Thread-15 (_run_job):15244 [wandb_run.py:_finish():2164] finishing run senna-renting-radboud-university/Pendulum-TD3/683jggrk
2024-10-23 11:03:24,475 INFO    Thread-15 (_run_job):15244 [jupyter.py:save_history():459] not saving jupyter history
2024-10-23 11:03:24,475 INFO    Thread-15 (_run_job):15244 [jupyter.py:save_ipynb():387] not saving jupyter notebook
2024-10-23 11:03:24,476 INFO    Thread-15 (_run_job):15244 [wandb_init.py:_jupyter_teardown():460] cleaning up jupyter logic
2024-10-23 11:03:24,476 INFO    Thread-15 (_run_job):15244 [wandb_run.py:_atexit_cleanup():2428] got exitcode: 1
2024-10-23 11:03:24,476 INFO    Thread-15 (_run_job):15244 [wandb_run.py:_restore():2410] restore
2024-10-23 11:03:24,476 INFO    Thread-15 (_run_job):15244 [wandb_run.py:_restore():2416] restore done
2024-10-23 11:03:24,476 INFO    Thread-15 (_run_job):15244 [wandb_run.py:_restore():2410] restore
2024-10-23 11:03:24,476 INFO    Thread-15 (_run_job):15244 [wandb_run.py:_restore():2416] restore done
2024-10-23 11:03:24,476 ERROR   Thread-15 (_run_job):15244 [wandb_run.py:_atexit_cleanup():2449] Problem finishing run
Traceback (most recent call last):
  File "C:\Users\31614\anaconda3\Lib\site-packages\wandb\agents\pyagent.py", line 306, in _run_job
    self._function()
  File "C:\Users\31614\Documents\AI_course_stuff\RLForaging Thesis\RLForagingAgents\RL-models\TD3\train_loops.py", line 84, in wandb_train_td3
    with wandb.init(config=config) as run:
         ^^^^^^^^^^^^^^^^^^^^^^^^^
  File "C:\Users\31614\anaconda3\Lib\site-packages\wandb\sdk\wandb_init.py", line 1266, in init
    wandb._sentry.reraise(e)
  File "C:\Users\31614\anaconda3\Lib\site-packages\wandb\analytics\sentry.py", line 155, in reraise
    raise exc.with_traceback(sys.exc_info()[2])
  File "C:\Users\31614\anaconda3\Lib\site-packages\wandb\sdk\wandb_init.py", line 1252, in init
    return wi.init()
           ^^^^^^^^^
  File "C:\Users\31614\anaconda3\Lib\site-packages\wandb\sdk\wandb_init.py", line 906, in init
    run._on_start()
  File "C:\Users\31614\anaconda3\Lib\site-packages\wandb\sdk\wandb_run.py", line 2505, in _on_start
    self._backend.interface.publish_python_packages(working_set())
  File "C:\Users\31614\anaconda3\Lib\site-packages\wandb\sdk\interface\interface.py", line 303, in publish_python_packages
    self._publish_python_packages(python_packages)
  File "C:\Users\31614\anaconda3\Lib\site-packages\wandb\sdk\interface\interface_shared.py", line 390, in _publish_python_packages
    self._publish(rec)
  File "C:\Users\31614\anaconda3\Lib\site-packages\wandb\sdk\interface\interface_sock.py", line 51, in _publish
    self._sock_client.send_record_publish(record)
  File "C:\Users\31614\anaconda3\Lib\site-packages\wandb\sdk\lib\sock_client.py", line 225, in send_record_publish
    self.send_server_request(server_req)
  File "C:\Users\31614\anaconda3\Lib\site-packages\wandb\sdk\lib\sock_client.py", line 157, in send_server_request
    self._send_message(msg)
  File "C:\Users\31614\anaconda3\Lib\site-packages\wandb\sdk\lib\sock_client.py", line 154, in _send_message
    self._sendall_with_error_handle(header + data)
  File "C:\Users\31614\anaconda3\Lib\site-packages\wandb\sdk\lib\sock_client.py", line 132, in _sendall_with_error_handle
    sent = self._sock.send(data)
           ^^^^^^^^^^^^^^^^^^^^^
ConnectionResetError: [WinError 10054] An existing connection was forcibly closed by the remote host

During handling of the above exception, another exception occurred:

Traceback (most recent call last):
  File "C:\Users\31614\anaconda3\Lib\site-packages\wandb\sdk\wandb_run.py", line 2440, in _atexit_cleanup
    self._on_finish()
  File "C:\Users\31614\anaconda3\Lib\site-packages\wandb\sdk\wandb_run.py", line 2678, in _on_finish
    exit_handle = self._backend.interface.deliver_exit(self._exit_code)
                  ^^^^^^^^^^^^^^^^^^^^^^^^^^^^^^^^^^^^^^^^^^^^^^^^^^^^^
  File "C:\Users\31614\anaconda3\Lib\site-packages\wandb\sdk\interface\interface.py", line 940, in deliver_exit
    return self._deliver_exit(exit_data)
           ^^^^^^^^^^^^^^^^^^^^^^^^^^^^^
  File "C:\Users\31614\anaconda3\Lib\site-packages\wandb\sdk\interface\interface_shared.py", line 479, in _deliver_exit
    return self._deliver_record(record)
           ^^^^^^^^^^^^^^^^^^^^^^^^^^^^
  File "C:\Users\31614\anaconda3\Lib\site-packages\wandb\sdk\interface\interface_shared.py", line 452, in _deliver_record
    handle = mailbox._deliver_record(record, interface=self)
             ^^^^^^^^^^^^^^^^^^^^^^^^^^^^^^^^^^^^^^^^^^^^^^^
  File "C:\Users\31614\anaconda3\Lib\site-packages\wandb\sdk\lib\mailbox.py", line 455, in _deliver_record
    interface._publish(record)
  File "C:\Users\31614\anaconda3\Lib\site-packages\wandb\sdk\interface\interface_sock.py", line 51, in _publish
    self._sock_client.send_record_publish(record)
  File "C:\Users\31614\anaconda3\Lib\site-packages\wandb\sdk\lib\sock_client.py", line 225, in send_record_publish
    self.send_server_request(server_req)
  File "C:\Users\31614\anaconda3\Lib\site-packages\wandb\sdk\lib\sock_client.py", line 157, in send_server_request
    self._send_message(msg)
  File "C:\Users\31614\anaconda3\Lib\site-packages\wandb\sdk\lib\sock_client.py", line 154, in _send_message
    self._sendall_with_error_handle(header + data)
  File "C:\Users\31614\anaconda3\Lib\site-packages\wandb\sdk\lib\sock_client.py", line 132, in _sendall_with_error_handle
    sent = self._sock.send(data)
           ^^^^^^^^^^^^^^^^^^^^^
ConnectionResetError: [WinError 10054] An existing connection was forcibly closed by the remote host
