2024-10-23 15:35:48,413 INFO    Thread-14 (_run_job):18592 [wandb_setup.py:_flush():79] Current SDK version is 0.18.3
2024-10-23 15:35:48,413 INFO    Thread-14 (_run_job):18592 [wandb_setup.py:_flush():79] Configure stats pid to 18592
2024-10-23 15:35:48,413 INFO    Thread-14 (_run_job):18592 [wandb_setup.py:_flush():79] Loading settings from C:\Users\31614\.config\wandb\settings
2024-10-23 15:35:48,413 INFO    Thread-14 (_run_job):18592 [wandb_setup.py:_flush():79] Loading settings from C:\Users\31614\Documents\AI_course_stuff\RLForaging Thesis\RLForagingAgents\RL-models\TD3\wandb\settings
2024-10-23 15:35:48,413 INFO    Thread-14 (_run_job):18592 [wandb_setup.py:_flush():79] Loading settings from environment variables: {'project': 'Pendulum-TD3', 'entity': 'senna-renting-radboud-university', 'root_dir': 'C:\\Users\\31614\\Documents\\AI_course_stuff\\RLForaging Thesis\\RLForagingAgents\\RL-models\\TD3', 'run_id': 'm73rfs3r', 'sweep_param_path': 'C:\\Users\\31614\\Documents\\AI_course_stuff\\RLForaging Thesis\\RLForagingAgents\\RL-models\\TD3\\wandb\\sweep-rsq2gnk1\\config-m73rfs3r.yaml', 'sweep_id': 'rsq2gnk1'}
2024-10-23 15:35:48,414 INFO    Thread-14 (_run_job):18592 [wandb_setup.py:_flush():79] Applying setup settings: {'mode': None, '_disable_service': None}
2024-10-23 15:35:48,414 INFO    Thread-14 (_run_job):18592 [wandb_setup.py:_flush():79] Inferring run settings from compute environment: {'program': '<python with no main file>'}
2024-10-23 15:35:48,414 INFO    Thread-14 (_run_job):18592 [wandb_setup.py:_flush():79] Applying login settings: {}
2024-10-23 15:35:48,414 INFO    Thread-14 (_run_job):18592 [wandb_init.py:_log_setup():532] Logging user logs to C:\Users\31614\Documents\AI_course_stuff\RLForaging Thesis\RLForagingAgents\RL-models\TD3\wandb\run-20241023_153548-m73rfs3r\logs\debug.log
2024-10-23 15:35:48,414 INFO    Thread-14 (_run_job):18592 [wandb_init.py:_log_setup():533] Logging internal logs to C:\Users\31614\Documents\AI_course_stuff\RLForaging Thesis\RLForagingAgents\RL-models\TD3\wandb\run-20241023_153548-m73rfs3r\logs\debug-internal.log
2024-10-23 15:35:48,414 INFO    Thread-14 (_run_job):18592 [wandb_init.py:_jupyter_setup():478] configuring jupyter hooks <wandb.sdk.wandb_init._WandbInit object at 0x0000024E601FB830>
2024-10-23 15:35:48,414 INFO    Thread-14 (_run_job):18592 [wandb_init.py:init():617] calling init triggers
2024-10-23 15:35:48,414 INFO    Thread-14 (_run_job):18592 [wandb_init.py:init():624] wandb.init called with sweep_config: {'batch_size': 256, 'buffer_size': 50000, 'gamma': 0.99, 'lr_actor': 0.0003926041243366343, 'lr_critic': 0.0011531561210417457, 'max_length_episode': 200, 'noise_clip': 1.5746563679483423, 'num_episodes': 100, 'policy_interval': 2, 'sigma': 0.7588966253279242, 'sigma_explore': 0.7195879361445231, 'tau': 0.08193415495853008, 'warmup_amount': 100}
config: {}
2024-10-23 15:35:48,414 INFO    Thread-14 (_run_job):18592 [wandb_init.py:init():667] starting backend
2024-10-23 15:35:48,414 INFO    Thread-14 (_run_job):18592 [wandb_init.py:init():671] sending inform_init request
2024-10-23 15:35:48,422 INFO    Thread-14 (_run_job):18592 [backend.py:_multiprocessing_setup():104] multiprocessing start_methods=spawn, using: spawn
2024-10-23 15:35:48,423 INFO    Thread-14 (_run_job):18592 [wandb_init.py:init():684] backend started and connected
2024-10-23 15:35:48,439 INFO    Thread-14 (_run_job):18592 [wandb_run.py:_config_callback():1394] config_cb None None {'batch_size': 256, 'buffer_size': 50000, 'gamma': 0.99, 'lr_actor': 0.0003926041243366343, 'lr_critic': 0.0011531561210417457, 'max_length_episode': 200, 'noise_clip': 1.5746563679483423, 'num_episodes': 100, 'policy_interval': 2, 'sigma': 0.7588966253279242, 'sigma_explore': 0.7195879361445231, 'tau': 0.08193415495853008, 'warmup_amount': 100}
2024-10-23 15:35:48,440 INFO    Thread-14 (_run_job):18592 [wandb_run.py:_label_probe_notebook():1346] probe notebook
2024-10-23 15:35:48,440 INFO    Thread-14 (_run_job):18592 [wandb_run.py:_label_probe_notebook():1356] Unable to probe notebook: 'NoneType' object has no attribute 'get'
2024-10-23 15:35:48,440 INFO    Thread-14 (_run_job):18592 [wandb_init.py:init():779] updated telemetry
2024-10-23 15:35:48,478 INFO    Thread-14 (_run_job):18592 [wandb_init.py:init():812] communicating run to backend with 90.0 second timeout
2024-10-23 15:35:48,722 INFO    Thread-14 (_run_job):18592 [wandb_init.py:init():863] starting run threads in backend
2024-10-23 15:35:49,144 WARNING MsgRouterThr:18592 [router.py:message_loop():77] message_loop has been closed
2024-10-23 15:35:49,316 ERROR   Thread-14 (_run_job):18592 [wandb_init.py:init():1262] error in wandb.init()
Traceback (most recent call last):
  File "C:\Users\31614\anaconda3\Lib\site-packages\wandb\sdk\wandb_init.py", line 1252, in init
    return wi.init()
           ^^^^^^^^^
  File "C:\Users\31614\anaconda3\Lib\site-packages\wandb\sdk\wandb_init.py", line 906, in init
    run._on_start()
  File "C:\Users\31614\anaconda3\Lib\site-packages\wandb\sdk\wandb_run.py", line 2505, in _on_start
    self._backend.interface.publish_python_packages(working_set())
  File "C:\Users\31614\anaconda3\Lib\site-packages\wandb\sdk\interface\interface.py", line 303, in publish_python_packages
    self._publish_python_packages(python_packages)
  File "C:\Users\31614\anaconda3\Lib\site-packages\wandb\sdk\interface\interface_shared.py", line 390, in _publish_python_packages
    self._publish(rec)
  File "C:\Users\31614\anaconda3\Lib\site-packages\wandb\sdk\interface\interface_sock.py", line 51, in _publish
    self._sock_client.send_record_publish(record)
  File "C:\Users\31614\anaconda3\Lib\site-packages\wandb\sdk\lib\sock_client.py", line 225, in send_record_publish
    self.send_server_request(server_req)
  File "C:\Users\31614\anaconda3\Lib\site-packages\wandb\sdk\lib\sock_client.py", line 157, in send_server_request
    self._send_message(msg)
  File "C:\Users\31614\anaconda3\Lib\site-packages\wandb\sdk\lib\sock_client.py", line 154, in _send_message
    self._sendall_with_error_handle(header + data)
  File "C:\Users\31614\anaconda3\Lib\site-packages\wandb\sdk\lib\sock_client.py", line 132, in _sendall_with_error_handle
    sent = self._sock.send(data)
           ^^^^^^^^^^^^^^^^^^^^^
ConnectionResetError: [WinError 10054] An existing connection was forcibly closed by the remote host
2024-10-23 15:35:49,622 INFO    Thread-14 (_run_job):18592 [wandb_run.py:_finish():2164] finishing run senna-renting-radboud-university/Pendulum-TD3/m73rfs3r
2024-10-23 15:35:49,622 INFO    Thread-14 (_run_job):18592 [jupyter.py:save_history():459] not saving jupyter history
2024-10-23 15:35:49,623 INFO    Thread-14 (_run_job):18592 [jupyter.py:save_ipynb():387] not saving jupyter notebook
2024-10-23 15:35:49,623 INFO    Thread-14 (_run_job):18592 [wandb_init.py:_jupyter_teardown():460] cleaning up jupyter logic
2024-10-23 15:35:49,623 INFO    Thread-14 (_run_job):18592 [wandb_run.py:_atexit_cleanup():2428] got exitcode: 1
2024-10-23 15:35:49,623 INFO    Thread-14 (_run_job):18592 [wandb_run.py:_restore():2410] restore
2024-10-23 15:35:49,623 INFO    Thread-14 (_run_job):18592 [wandb_run.py:_restore():2416] restore done
2024-10-23 15:35:49,623 INFO    Thread-14 (_run_job):18592 [wandb_run.py:_restore():2410] restore
2024-10-23 15:35:49,623 INFO    Thread-14 (_run_job):18592 [wandb_run.py:_restore():2416] restore done
2024-10-23 15:35:49,623 ERROR   Thread-14 (_run_job):18592 [wandb_run.py:_atexit_cleanup():2449] Problem finishing run
Traceback (most recent call last):
  File "C:\Users\31614\anaconda3\Lib\site-packages\wandb\agents\pyagent.py", line 306, in _run_job
    self._function()
  File "C:\Users\31614\anaconda3\Lib\site-packages\jax\_src\traceback_util.py", line 180, in reraise_with_filtered_traceback
    return fun(*args, **kwargs)
           ^^^^^^^^^^^^^^^^^^^^
  File "C:\Users\31614\anaconda3\Lib\site-packages\jax\_src\pjit.py", line 356, in cache_miss
    outs, out_flat, out_tree, args_flat, jaxpr, attrs_tracked = _python_pjit_helper(
                                                                ^^^^^^^^^^^^^^^^^^^^
  File "C:\Users\31614\anaconda3\Lib\site-packages\jax\_src\pjit.py", line 179, in _python_pjit_helper
    p, args_flat = _infer_params(fun, jit_info, args, kwargs)
                   ^^^^^^^^^^^^^^^^^^^^^^^^^^^^^^^^^^^^^^^^^^
  File "C:\Users\31614\anaconda3\Lib\site-packages\jax\_src\pjit.py", line 773, in _infer_params
    p, args_flat = _infer_params_impl(
                   ^^^^^^^^^^^^^^^^^^^
  File "C:\Users\31614\anaconda3\Lib\site-packages\jax\_src\pjit.py", line 670, in _infer_params_impl
    jaxpr, consts, out_avals, attrs_tracked = _create_pjit_jaxpr(
                                              ^^^^^^^^^^^^^^^^^^^
  File "C:\Users\31614\anaconda3\Lib\site-packages\jax\_src\linear_util.py", line 352, in memoized_fun
    ans = call(fun, *args)
          ^^^^^^^^^^^^^^^^
  File "C:\Users\31614\anaconda3\Lib\site-packages\jax\_src\pjit.py", line 1314, in _create_pjit_jaxpr
    jaxpr, global_out_avals, consts, attrs_tracked = pe.trace_to_jaxpr_dynamic(
                                                     ^^^^^^^^^^^^^^^^^^^^^^^^^^
  File "C:\Users\31614\anaconda3\Lib\site-packages\jax\_src\profiler.py", line 333, in wrapper
    return func(*args, **kwargs)
           ^^^^^^^^^^^^^^^^^^^^^
  File "C:\Users\31614\anaconda3\Lib\site-packages\jax\_src\interpreters\partial_eval.py", line 2278, in trace_to_jaxpr_dynamic
    jaxpr, out_avals, consts, attrs_tracked = trace_to_subjaxpr_dynamic(
                                              ^^^^^^^^^^^^^^^^^^^^^^^^^^
  File "C:\Users\31614\anaconda3\Lib\site-packages\jax\_src\interpreters\partial_eval.py", line 2301, in trace_to_subjaxpr_dynamic
    ans = fun.call_wrapped(*in_tracers_)
          ^^^^^^^^^^^^^^^^^^^^^^^^^^^^^^
  File "C:\Users\31614\anaconda3\Lib\site-packages\jax\_src\linear_util.py", line 193, in call_wrapped
    ans = self.f(*args, **dict(self.params, **kwargs))
          ^^^^^^^^^^^^^^^^^^^^^^^^^^^^^^^^^^^^^^^^^^^^
  File "C:\Users\31614\Documents\AI_course_stuff\RLForaging Thesis\RLForagingAgents\RL-models\TD3\train_loops.py", line 85, in wandb_train_td3
    with wandb.init(config=config) as run:
         ^^^^^^^^^^^^^^^^^^^^^^^^^
  File "C:\Users\31614\anaconda3\Lib\site-packages\wandb\sdk\wandb_init.py", line 1266, in init
    wandb._sentry.reraise(e)
  File "C:\Users\31614\anaconda3\Lib\site-packages\wandb\analytics\sentry.py", line 155, in reraise
    raise exc.with_traceback(sys.exc_info()[2])
  File "C:\Users\31614\anaconda3\Lib\site-packages\wandb\sdk\wandb_init.py", line 1252, in init
    return wi.init()
           ^^^^^^^^^
  File "C:\Users\31614\anaconda3\Lib\site-packages\wandb\sdk\wandb_init.py", line 906, in init
    run._on_start()
  File "C:\Users\31614\anaconda3\Lib\site-packages\wandb\sdk\wandb_run.py", line 2505, in _on_start
    self._backend.interface.publish_python_packages(working_set())
  File "C:\Users\31614\anaconda3\Lib\site-packages\wandb\sdk\interface\interface.py", line 303, in publish_python_packages
    self._publish_python_packages(python_packages)
  File "C:\Users\31614\anaconda3\Lib\site-packages\wandb\sdk\interface\interface_shared.py", line 390, in _publish_python_packages
    self._publish(rec)
  File "C:\Users\31614\anaconda3\Lib\site-packages\wandb\sdk\interface\interface_sock.py", line 51, in _publish
    self._sock_client.send_record_publish(record)
  File "C:\Users\31614\anaconda3\Lib\site-packages\wandb\sdk\lib\sock_client.py", line 225, in send_record_publish
    self.send_server_request(server_req)
  File "C:\Users\31614\anaconda3\Lib\site-packages\wandb\sdk\lib\sock_client.py", line 157, in send_server_request
    self._send_message(msg)
  File "C:\Users\31614\anaconda3\Lib\site-packages\wandb\sdk\lib\sock_client.py", line 154, in _send_message
    self._sendall_with_error_handle(header + data)
  File "C:\Users\31614\anaconda3\Lib\site-packages\wandb\sdk\lib\sock_client.py", line 132, in _sendall_with_error_handle
    sent = self._sock.send(data)
           ^^^^^^^^^^^^^^^^^^^^^
ConnectionResetError: [WinError 10054] An existing connection was forcibly closed by the remote host

During handling of the above exception, another exception occurred:

Traceback (most recent call last):
  File "C:\Users\31614\anaconda3\Lib\site-packages\wandb\sdk\wandb_run.py", line 2440, in _atexit_cleanup
    self._on_finish()
  File "C:\Users\31614\anaconda3\Lib\site-packages\wandb\sdk\wandb_run.py", line 2678, in _on_finish
    exit_handle = self._backend.interface.deliver_exit(self._exit_code)
                  ^^^^^^^^^^^^^^^^^^^^^^^^^^^^^^^^^^^^^^^^^^^^^^^^^^^^^
  File "C:\Users\31614\anaconda3\Lib\site-packages\wandb\sdk\interface\interface.py", line 940, in deliver_exit
    return self._deliver_exit(exit_data)
           ^^^^^^^^^^^^^^^^^^^^^^^^^^^^^
  File "C:\Users\31614\anaconda3\Lib\site-packages\wandb\sdk\interface\interface_shared.py", line 479, in _deliver_exit
    return self._deliver_record(record)
           ^^^^^^^^^^^^^^^^^^^^^^^^^^^^
  File "C:\Users\31614\anaconda3\Lib\site-packages\wandb\sdk\interface\interface_shared.py", line 452, in _deliver_record
    handle = mailbox._deliver_record(record, interface=self)
             ^^^^^^^^^^^^^^^^^^^^^^^^^^^^^^^^^^^^^^^^^^^^^^^
  File "C:\Users\31614\anaconda3\Lib\site-packages\wandb\sdk\lib\mailbox.py", line 455, in _deliver_record
    interface._publish(record)
  File "C:\Users\31614\anaconda3\Lib\site-packages\wandb\sdk\interface\interface_sock.py", line 51, in _publish
    self._sock_client.send_record_publish(record)
  File "C:\Users\31614\anaconda3\Lib\site-packages\wandb\sdk\lib\sock_client.py", line 225, in send_record_publish
    self.send_server_request(server_req)
  File "C:\Users\31614\anaconda3\Lib\site-packages\wandb\sdk\lib\sock_client.py", line 157, in send_server_request
    self._send_message(msg)
  File "C:\Users\31614\anaconda3\Lib\site-packages\wandb\sdk\lib\sock_client.py", line 154, in _send_message
    self._sendall_with_error_handle(header + data)
  File "C:\Users\31614\anaconda3\Lib\site-packages\wandb\sdk\lib\sock_client.py", line 132, in _sendall_with_error_handle
    sent = self._sock.send(data)
           ^^^^^^^^^^^^^^^^^^^^^
ConnectionResetError: [WinError 10054] An existing connection was forcibly closed by the remote host
