2024-10-23 17:37:32,935 INFO    Thread-15 (_run_job):13464 [wandb_setup.py:_flush():79] Current SDK version is 0.18.3
2024-10-23 17:37:32,936 INFO    Thread-15 (_run_job):13464 [wandb_setup.py:_flush():79] Configure stats pid to 13464
2024-10-23 17:37:32,936 INFO    Thread-15 (_run_job):13464 [wandb_setup.py:_flush():79] Loading settings from C:\Users\31614\.config\wandb\settings
2024-10-23 17:37:32,936 INFO    Thread-15 (_run_job):13464 [wandb_setup.py:_flush():79] Loading settings from C:\Users\31614\Documents\AI_course_stuff\RLForaging Thesis\RLForagingAgents\RL-models\TD3\wandb\settings
2024-10-23 17:37:32,936 INFO    Thread-15 (_run_job):13464 [wandb_setup.py:_flush():79] Loading settings from environment variables: {'project': 'Pendulum-TD3', 'entity': 'senna-renting-radboud-university', 'root_dir': 'C:\\Users\\31614\\Documents\\AI_course_stuff\\RLForaging Thesis\\RLForagingAgents\\RL-models\\TD3', 'run_id': '5n69vsf2', 'sweep_param_path': 'C:\\Users\\31614\\Documents\\AI_course_stuff\\RLForaging Thesis\\RLForagingAgents\\RL-models\\TD3\\wandb\\sweep-eblhatnh\\config-5n69vsf2.yaml', 'sweep_id': 'eblhatnh'}
2024-10-23 17:37:32,936 INFO    Thread-15 (_run_job):13464 [wandb_setup.py:_flush():79] Applying setup settings: {'mode': None, '_disable_service': None}
2024-10-23 17:37:32,936 INFO    Thread-15 (_run_job):13464 [wandb_setup.py:_flush():79] Inferring run settings from compute environment: {'program': '<python with no main file>'}
2024-10-23 17:37:32,936 INFO    Thread-15 (_run_job):13464 [wandb_setup.py:_flush():79] Applying login settings: {}
2024-10-23 17:37:32,936 INFO    Thread-15 (_run_job):13464 [wandb_init.py:_log_setup():532] Logging user logs to C:\Users\31614\Documents\AI_course_stuff\RLForaging Thesis\RLForagingAgents\RL-models\TD3\wandb\run-20241023_173732-5n69vsf2\logs\debug.log
2024-10-23 17:37:32,936 INFO    Thread-15 (_run_job):13464 [wandb_init.py:_log_setup():533] Logging internal logs to C:\Users\31614\Documents\AI_course_stuff\RLForaging Thesis\RLForagingAgents\RL-models\TD3\wandb\run-20241023_173732-5n69vsf2\logs\debug-internal.log
2024-10-23 17:37:32,937 INFO    Thread-15 (_run_job):13464 [wandb_init.py:_jupyter_setup():478] configuring jupyter hooks <wandb.sdk.wandb_init._WandbInit object at 0x00000211C2237590>
2024-10-23 17:37:32,937 INFO    Thread-15 (_run_job):13464 [wandb_init.py:init():617] calling init triggers
2024-10-23 17:37:32,937 INFO    Thread-15 (_run_job):13464 [wandb_init.py:init():624] wandb.init called with sweep_config: {'batch_size': 256, 'buffer_size': 50000, 'gamma': 0.99, 'lr_actor': 0.0001643804008339273, 'lr_critic': 0.00033854687683939374, 'max_length_episode': 200, 'noise_clip': 0.21059150252314568, 'num_episodes': 100, 'policy_interval': 2, 'sigma': 0.2385302156605262, 'sigma_explore': 0.33369923070847796, 'tau': 0.008104735267642105, 'warmup_amount': 100}
config: {}
2024-10-23 17:37:32,937 INFO    Thread-15 (_run_job):13464 [wandb_init.py:init():667] starting backend
2024-10-23 17:37:32,937 INFO    Thread-15 (_run_job):13464 [wandb_init.py:init():671] sending inform_init request
2024-10-23 17:37:32,945 INFO    Thread-15 (_run_job):13464 [backend.py:_multiprocessing_setup():104] multiprocessing start_methods=spawn, using: spawn
2024-10-23 17:37:32,946 INFO    Thread-15 (_run_job):13464 [wandb_init.py:init():684] backend started and connected
2024-10-23 17:37:32,960 INFO    Thread-15 (_run_job):13464 [wandb_run.py:_config_callback():1394] config_cb None None {'batch_size': 256, 'buffer_size': 50000, 'gamma': 0.99, 'lr_actor': 0.0001643804008339273, 'lr_critic': 0.00033854687683939374, 'max_length_episode': 200, 'noise_clip': 0.21059150252314568, 'num_episodes': 100, 'policy_interval': 2, 'sigma': 0.2385302156605262, 'sigma_explore': 0.33369923070847796, 'tau': 0.008104735267642105, 'warmup_amount': 100}
2024-10-23 17:37:32,961 INFO    Thread-15 (_run_job):13464 [wandb_run.py:_label_probe_notebook():1346] probe notebook
2024-10-23 17:37:32,961 INFO    Thread-15 (_run_job):13464 [wandb_run.py:_label_probe_notebook():1356] Unable to probe notebook: 'NoneType' object has no attribute 'get'
2024-10-23 17:37:32,962 INFO    Thread-15 (_run_job):13464 [wandb_init.py:init():779] updated telemetry
2024-10-23 17:37:32,994 INFO    Thread-15 (_run_job):13464 [wandb_init.py:init():812] communicating run to backend with 90.0 second timeout
2024-10-23 17:37:33,215 INFO    Thread-15 (_run_job):13464 [wandb_init.py:init():863] starting run threads in backend
2024-10-23 17:37:33,756 INFO    Thread-15 (_run_job):13464 [wandb_run.py:_console_start():2465] atexit reg
2024-10-23 17:37:33,757 INFO    Thread-15 (_run_job):13464 [wandb_run.py:_redirect():2313] redirect: wrap_raw
2024-10-23 17:37:33,757 INFO    Thread-15 (_run_job):13464 [wandb_run.py:_redirect():2378] Wrapping output streams.
2024-10-23 17:37:33,757 INFO    Thread-15 (_run_job):13464 [wandb_run.py:_redirect():2403] Redirects installed.
2024-10-23 17:37:33,757 INFO    Thread-15 (_run_job):13464 [wandb_init.py:init():907] run started, returning control to user process
2024-10-23 17:37:56,340 INFO    Thread-15 (_run_job):13464 [wandb_run.py:_finish():2164] finishing run senna-renting-radboud-university/Pendulum-TD3/5n69vsf2
2024-10-23 17:37:56,341 INFO    Thread-15 (_run_job):13464 [jupyter.py:save_history():459] not saving jupyter history
2024-10-23 17:37:56,341 INFO    Thread-15 (_run_job):13464 [jupyter.py:save_ipynb():387] not saving jupyter notebook
2024-10-23 17:37:56,341 INFO    Thread-15 (_run_job):13464 [wandb_init.py:_jupyter_teardown():460] cleaning up jupyter logic
2024-10-23 17:37:56,341 INFO    Thread-15 (_run_job):13464 [wandb_run.py:_atexit_cleanup():2428] got exitcode: 1
2024-10-23 17:37:56,341 INFO    Thread-15 (_run_job):13464 [wandb_run.py:_restore():2410] restore
2024-10-23 17:37:56,342 INFO    Thread-15 (_run_job):13464 [wandb_run.py:_restore():2416] restore done
2024-10-23 17:37:56,517 WARNING MsgRouterThr:13464 [router.py:message_loop():77] message_loop has been closed
2024-10-23 17:37:57,350 INFO    Thread-15 (_run_job):13464 [wandb_run.py:_restore():2410] restore
2024-10-23 17:37:57,351 INFO    Thread-15 (_run_job):13464 [wandb_run.py:_restore():2416] restore done
2024-10-23 17:37:57,351 ERROR   Thread-15 (_run_job):13464 [wandb_run.py:_atexit_cleanup():2449] Problem finishing run
Traceback (most recent call last):
  File "C:\Users\31614\Documents\AI_course_stuff\RLForaging Thesis\RLForagingAgents\RL-models\TD3\train_loops.py", line 142, in wandb_train_td3
    best_avg_return, best_policy = jax.lax.cond(avg_return > best_avg_return, new_policy, same_policy, best_avg_return, avg_return, best_policy, td3.get_policy())
                                   ^^^^^^^^^^^^^^^^^^^^^^^^^^^^^^^^^^^^^^^^^^^^^^^^^^^^^^^^^^^^^^^^^^^^^^^^^^^^^^^^^^^^^^^^^^^^^^^^^^^^^^^^^^^^^^^^^^^^^^^^^^^^^^^
  File "C:\Users\31614\anaconda3\Lib\site-packages\jax\_src\traceback_util.py", line 180, in reraise_with_filtered_traceback
    return fun(*args, **kwargs)
           ^^^^^^^^^^^^^^^^^^^^
  File "C:\Users\31614\anaconda3\Lib\site-packages\jax\_src\lax\control_flow\conditionals.py", line 301, in cond
    return _cond(*args, **kwargs)
           ^^^^^^^^^^^^^^^^^^^^^^
  File "C:\Users\31614\anaconda3\Lib\site-packages\jax\_src\lax\control_flow\conditionals.py", line 248, in _cond
    _check_tree_and_avals("true_fun and false_fun output",
  File "C:\Users\31614\anaconda3\Lib\site-packages\jax\_src\lax\control_flow\common.py", line 214, in _check_tree_and_avals
    raise TypeError(f"{what} must have identical types, got\n{diff}.")
TypeError: true_fun and false_fun output must have identical types, got
('DIFFERENT ShapedArray(float32[]) vs. ShapedArray(int32[], weak_type=True)', State({
  'l1': {
    'bias': VariableState(
      type=Param,
      value='ShapedArray(float32[256])'
    ),
    'kernel': VariableState(
      type=Param,
      value='ShapedArray(float32[3,256])'
    )
  },
  'l2': {
    'bias': VariableState(
      type=Param,
      value='ShapedArray(float32[256])'
    ),
    'kernel': VariableState(
      type=Param,
      value='ShapedArray(float32[256,256])'
    )
  },
  'l3': {
    'bias': VariableState(
      type=Param,
      value='ShapedArray(float32[1])'
    ),
    'kernel': VariableState(
      type=Param,
      value='ShapedArray(float32[256,1])'
    )
  }
})).

During handling of the above exception, another exception occurred:

Traceback (most recent call last):
  File "C:\Users\31614\anaconda3\Lib\site-packages\wandb\sdk\wandb_run.py", line 2440, in _atexit_cleanup
    self._on_finish()
  File "C:\Users\31614\anaconda3\Lib\site-packages\wandb\sdk\wandb_run.py", line 2682, in _on_finish
    _ = exit_handle.wait(timeout=-1, on_progress=self._on_progress_exit)
        ^^^^^^^^^^^^^^^^^^^^^^^^^^^^^^^^^^^^^^^^^^^^^^^^^^^^^^^^^^^^^^^^
  File "C:\Users\31614\anaconda3\Lib\site-packages\wandb\sdk\lib\mailbox.py", line 298, in wait
    on_probe(probe_handle)
  File "C:\Users\31614\anaconda3\Lib\site-packages\wandb\sdk\wandb_run.py", line 2654, in _on_probe_exit
    handle = self._backend.interface.deliver_poll_exit()
             ^^^^^^^^^^^^^^^^^^^^^^^^^^^^^^^^^^^^^^^^^^^
  File "C:\Users\31614\anaconda3\Lib\site-packages\wandb\sdk\interface\interface.py", line 948, in deliver_poll_exit
    return self._deliver_poll_exit(poll_exit)
           ^^^^^^^^^^^^^^^^^^^^^^^^^^^^^^^^^^
  File "C:\Users\31614\anaconda3\Lib\site-packages\wandb\sdk\interface\interface_shared.py", line 483, in _deliver_poll_exit
    return self._deliver_record(record)
           ^^^^^^^^^^^^^^^^^^^^^^^^^^^^
  File "C:\Users\31614\anaconda3\Lib\site-packages\wandb\sdk\interface\interface_shared.py", line 452, in _deliver_record
    handle = mailbox._deliver_record(record, interface=self)
             ^^^^^^^^^^^^^^^^^^^^^^^^^^^^^^^^^^^^^^^^^^^^^^^
  File "C:\Users\31614\anaconda3\Lib\site-packages\wandb\sdk\lib\mailbox.py", line 455, in _deliver_record
    interface._publish(record)
  File "C:\Users\31614\anaconda3\Lib\site-packages\wandb\sdk\interface\interface_sock.py", line 51, in _publish
    self._sock_client.send_record_publish(record)
  File "C:\Users\31614\anaconda3\Lib\site-packages\wandb\sdk\lib\sock_client.py", line 225, in send_record_publish
    self.send_server_request(server_req)
  File "C:\Users\31614\anaconda3\Lib\site-packages\wandb\sdk\lib\sock_client.py", line 157, in send_server_request
    self._send_message(msg)
  File "C:\Users\31614\anaconda3\Lib\site-packages\wandb\sdk\lib\sock_client.py", line 154, in _send_message
    self._sendall_with_error_handle(header + data)
  File "C:\Users\31614\anaconda3\Lib\site-packages\wandb\sdk\lib\sock_client.py", line 132, in _sendall_with_error_handle
    sent = self._sock.send(data)
           ^^^^^^^^^^^^^^^^^^^^^
ConnectionResetError: [WinError 10054] An existing connection was forcibly closed by the remote host
