2024-10-23 18:54:08,354 INFO    Thread-11 (_run_job):28752 [wandb_setup.py:_flush():79] Current SDK version is 0.18.3
2024-10-23 18:54:08,354 INFO    Thread-11 (_run_job):28752 [wandb_setup.py:_flush():79] Configure stats pid to 28752
2024-10-23 18:54:08,354 INFO    Thread-11 (_run_job):28752 [wandb_setup.py:_flush():79] Loading settings from C:\Users\31614\.config\wandb\settings
2024-10-23 18:54:08,354 INFO    Thread-11 (_run_job):28752 [wandb_setup.py:_flush():79] Loading settings from C:\Users\31614\Documents\AI_course_stuff\RLForaging Thesis\RLForagingAgents\RL-models\TD3\wandb\settings
2024-10-23 18:54:08,354 INFO    Thread-11 (_run_job):28752 [wandb_setup.py:_flush():79] Loading settings from environment variables: {'project': 'Pendulum-TD3', 'entity': 'senna-renting-radboud-university', 'root_dir': 'C:\\Users\\31614\\Documents\\AI_course_stuff\\RLForaging Thesis\\RLForagingAgents\\RL-models\\TD3', 'sweep_id': 'vr1hj3pf', 'run_id': '4ng1esv0', 'sweep_param_path': 'C:\\Users\\31614\\Documents\\AI_course_stuff\\RLForaging Thesis\\RLForagingAgents\\RL-models\\TD3\\wandb\\sweep-vr1hj3pf\\config-4ng1esv0.yaml'}
2024-10-23 18:54:08,360 INFO    Thread-11 (_run_job):28752 [wandb_setup.py:_flush():79] Applying setup settings: {'mode': None, '_disable_service': None}
2024-10-23 18:54:08,360 INFO    Thread-11 (_run_job):28752 [wandb_setup.py:_flush():79] Inferring run settings from compute environment: {'program': '<python with no main file>'}
2024-10-23 18:54:08,360 INFO    Thread-11 (_run_job):28752 [wandb_setup.py:_flush():79] Applying login settings: {}
2024-10-23 18:54:08,360 INFO    Thread-11 (_run_job):28752 [wandb_init.py:_log_setup():532] Logging user logs to C:\Users\31614\Documents\AI_course_stuff\RLForaging Thesis\RLForagingAgents\RL-models\TD3\wandb\run-20241023_185408-4ng1esv0\logs\debug.log
2024-10-23 18:54:08,360 INFO    Thread-11 (_run_job):28752 [wandb_init.py:_log_setup():533] Logging internal logs to C:\Users\31614\Documents\AI_course_stuff\RLForaging Thesis\RLForagingAgents\RL-models\TD3\wandb\run-20241023_185408-4ng1esv0\logs\debug-internal.log
2024-10-23 18:54:08,360 INFO    Thread-11 (_run_job):28752 [wandb_init.py:_jupyter_setup():478] configuring jupyter hooks <wandb.sdk.wandb_init._WandbInit object at 0x00000221C71F3DA0>
2024-10-23 18:54:08,360 INFO    Thread-11 (_run_job):28752 [wandb_init.py:init():617] calling init triggers
2024-10-23 18:54:08,360 INFO    Thread-11 (_run_job):28752 [wandb_init.py:init():624] wandb.init called with sweep_config: {'batch_size': 256, 'buffer_size': 50000, 'gamma': 0.99, 'lr_actor': 0.00045444214253496376, 'lr_critic': 0.000910223712522918, 'max_length_episode': 200, 'noise_clip': 1.9145960537542503, 'num_episodes': 100, 'policy_interval': 2, 'sigma': 0.7849293380673268, 'sigma_explore': 0.7167872276417777, 'tau': 0.03529483391093068, 'warmup_amount': 10}
config: {}
2024-10-23 18:54:08,360 INFO    Thread-11 (_run_job):28752 [wandb_init.py:init():667] starting backend
2024-10-23 18:54:08,360 INFO    Thread-11 (_run_job):28752 [wandb_init.py:init():671] sending inform_init request
2024-10-23 18:54:08,372 INFO    Thread-11 (_run_job):28752 [backend.py:_multiprocessing_setup():104] multiprocessing start_methods=spawn, using: spawn
2024-10-23 18:54:08,373 INFO    Thread-11 (_run_job):28752 [wandb_init.py:init():684] backend started and connected
2024-10-23 18:54:08,393 INFO    Thread-11 (_run_job):28752 [wandb_run.py:_config_callback():1394] config_cb None None {'batch_size': 256, 'buffer_size': 50000, 'gamma': 0.99, 'lr_actor': 0.00045444214253496376, 'lr_critic': 0.000910223712522918, 'max_length_episode': 200, 'noise_clip': 1.9145960537542503, 'num_episodes': 100, 'policy_interval': 2, 'sigma': 0.7849293380673268, 'sigma_explore': 0.7167872276417777, 'tau': 0.03529483391093068, 'warmup_amount': 10}
2024-10-23 18:54:08,395 INFO    Thread-11 (_run_job):28752 [wandb_run.py:_label_probe_notebook():1346] probe notebook
2024-10-23 18:54:08,395 INFO    Thread-11 (_run_job):28752 [wandb_run.py:_label_probe_notebook():1356] Unable to probe notebook: 'NoneType' object has no attribute 'get'
2024-10-23 18:54:08,396 INFO    Thread-11 (_run_job):28752 [wandb_init.py:init():779] updated telemetry
2024-10-23 18:54:08,440 INFO    Thread-11 (_run_job):28752 [wandb_init.py:init():812] communicating run to backend with 90.0 second timeout
2024-10-23 18:54:08,776 INFO    Thread-11 (_run_job):28752 [wandb_init.py:init():863] starting run threads in backend
2024-10-23 18:54:09,591 INFO    Thread-11 (_run_job):28752 [wandb_run.py:_console_start():2465] atexit reg
2024-10-23 18:54:09,591 INFO    Thread-11 (_run_job):28752 [wandb_run.py:_redirect():2313] redirect: wrap_raw
2024-10-23 18:54:09,591 INFO    Thread-11 (_run_job):28752 [wandb_run.py:_redirect():2378] Wrapping output streams.
2024-10-23 18:54:09,591 INFO    Thread-11 (_run_job):28752 [wandb_run.py:_redirect():2403] Redirects installed.
2024-10-23 18:54:09,597 INFO    Thread-11 (_run_job):28752 [wandb_init.py:init():907] run started, returning control to user process
2024-10-24 14:44:42,584 INFO    Thread-10 (_heartbeat):28752 [retry.py:__call__():172] Retry attempt failed:
Traceback (most recent call last):
  File "C:\Users\31614\anaconda3\Lib\site-packages\urllib3\connection.py", line 196, in _new_conn
    sock = connection.create_connection(
           ^^^^^^^^^^^^^^^^^^^^^^^^^^^^^
  File "C:\Users\31614\anaconda3\Lib\site-packages\urllib3\util\connection.py", line 60, in create_connection
    for res in socket.getaddrinfo(host, port, family, socket.SOCK_STREAM):
               ^^^^^^^^^^^^^^^^^^^^^^^^^^^^^^^^^^^^^^^^^^^^^^^^^^^^^^^^^^
  File "C:\Users\31614\anaconda3\Lib\socket.py", line 964, in getaddrinfo
    for res in _socket.getaddrinfo(host, port, family, type, proto, flags):
               ^^^^^^^^^^^^^^^^^^^^^^^^^^^^^^^^^^^^^^^^^^^^^^^^^^^^^^^^^^^
socket.gaierror: [Errno 11001] getaddrinfo failed

The above exception was the direct cause of the following exception:

Traceback (most recent call last):
  File "C:\Users\31614\anaconda3\Lib\site-packages\urllib3\connectionpool.py", line 789, in urlopen
    response = self._make_request(
               ^^^^^^^^^^^^^^^^^^^
  File "C:\Users\31614\anaconda3\Lib\site-packages\urllib3\connectionpool.py", line 490, in _make_request
    raise new_e
  File "C:\Users\31614\anaconda3\Lib\site-packages\urllib3\connectionpool.py", line 466, in _make_request
    self._validate_conn(conn)
  File "C:\Users\31614\anaconda3\Lib\site-packages\urllib3\connectionpool.py", line 1095, in _validate_conn
    conn.connect()
  File "C:\Users\31614\anaconda3\Lib\site-packages\urllib3\connection.py", line 615, in connect
    self.sock = sock = self._new_conn()
                       ^^^^^^^^^^^^^^^^
  File "C:\Users\31614\anaconda3\Lib\site-packages\urllib3\connection.py", line 203, in _new_conn
    raise NameResolutionError(self.host, self, e) from e
urllib3.exceptions.NameResolutionError: <urllib3.connection.HTTPSConnection object at 0x00000221A0789AC0>: Failed to resolve 'api.wandb.ai' ([Errno 11001] getaddrinfo failed)

The above exception was the direct cause of the following exception:

Traceback (most recent call last):
  File "C:\Users\31614\anaconda3\Lib\site-packages\requests\adapters.py", line 589, in send
    resp = conn.urlopen(
           ^^^^^^^^^^^^^
  File "C:\Users\31614\anaconda3\Lib\site-packages\urllib3\connectionpool.py", line 843, in urlopen
    retries = retries.increment(
              ^^^^^^^^^^^^^^^^^^
  File "C:\Users\31614\anaconda3\Lib\site-packages\urllib3\util\retry.py", line 519, in increment
    raise MaxRetryError(_pool, url, reason) from reason  # type: ignore[arg-type]
    ^^^^^^^^^^^^^^^^^^^^^^^^^^^^^^^^^^^^^^^^^^^^^^^^^^^
urllib3.exceptions.MaxRetryError: HTTPSConnectionPool(host='api.wandb.ai', port=443): Max retries exceeded with url: /graphql (Caused by NameResolutionError("<urllib3.connection.HTTPSConnection object at 0x00000221A0789AC0>: Failed to resolve 'api.wandb.ai' ([Errno 11001] getaddrinfo failed)"))

During handling of the above exception, another exception occurred:

Traceback (most recent call last):
  File "C:\Users\31614\anaconda3\Lib\site-packages\wandb\sdk\lib\retry.py", line 131, in __call__
    result = self._call_fn(*args, **kwargs)
             ^^^^^^^^^^^^^^^^^^^^^^^^^^^^^^
  File "C:\Users\31614\anaconda3\Lib\site-packages\wandb\sdk\internal\internal_api.py", line 347, in execute
    return self.client.execute(*args, **kwargs)  # type: ignore
           ^^^^^^^^^^^^^^^^^^^^^^^^^^^^^^^^^^^^
  File "C:\Users\31614\anaconda3\Lib\site-packages\wandb\vendor\gql-0.2.0\wandb_gql\client.py", line 52, in execute
    result = self._get_result(document, *args, **kwargs)
             ^^^^^^^^^^^^^^^^^^^^^^^^^^^^^^^^^^^^^^^^^^^
  File "C:\Users\31614\anaconda3\Lib\site-packages\wandb\vendor\gql-0.2.0\wandb_gql\client.py", line 60, in _get_result
    return self.transport.execute(document, *args, **kwargs)
           ^^^^^^^^^^^^^^^^^^^^^^^^^^^^^^^^^^^^^^^^^^^^^^^^^
  File "C:\Users\31614\anaconda3\Lib\site-packages\wandb\sdk\lib\gql_request.py", line 58, in execute
    request = self.session.post(self.url, **post_args)
              ^^^^^^^^^^^^^^^^^^^^^^^^^^^^^^^^^^^^^^^^
  File "C:\Users\31614\anaconda3\Lib\site-packages\requests\sessions.py", line 637, in post
    return self.request("POST", url, data=data, json=json, **kwargs)
           ^^^^^^^^^^^^^^^^^^^^^^^^^^^^^^^^^^^^^^^^^^^^^^^^^^^^^^^^^
  File "C:\Users\31614\anaconda3\Lib\site-packages\requests\sessions.py", line 589, in request
    resp = self.send(prep, **send_kwargs)
           ^^^^^^^^^^^^^^^^^^^^^^^^^^^^^^
  File "C:\Users\31614\anaconda3\Lib\site-packages\requests\sessions.py", line 703, in send
    r = adapter.send(request, **kwargs)
        ^^^^^^^^^^^^^^^^^^^^^^^^^^^^^^^
  File "C:\Users\31614\anaconda3\Lib\site-packages\requests\adapters.py", line 622, in send
    raise ConnectionError(e, request=request)
requests.exceptions.ConnectionError: HTTPSConnectionPool(host='api.wandb.ai', port=443): Max retries exceeded with url: /graphql (Caused by NameResolutionError("<urllib3.connection.HTTPSConnection object at 0x00000221A0789AC0>: Failed to resolve 'api.wandb.ai' ([Errno 11001] getaddrinfo failed)"))
2024-10-24 14:45:30,024 WARNING MsgRouterThr:28752 [router.py:message_loop():77] message_loop has been closed
